Workbook

Sheet README
A1: PIBN revised manuscript: plot-ready data for Figures 2, 3, 4
A3: Legend
A4: Blue text = measured values transcribed from the manuscript (Tables 2-4, Section 4.1 thickness data, Fig. 2c thermography).
A5: Black text = three-phase Lewis-Nielsen model, computed by live formulas from the Parameters sheet.
A6: Yellow fill = editable inputs (Parameters sheet). Change a parameter and every model series recalculates.
A8: Sheet -> figure panel
A9: Parameters constants of the model (eps_PI, eps_BN, A_BN, A_pore, lam_BN_eff, ...)
A10: Samples all ten films: composition, porosity (open/total), density, Cp, alpha, lambda, eps, tensile, CTE + model columns
A11: Fig2a_Dielectric eps (100 kHz) vs h-BN wt%: NP/HP measured, LN model at each film's open porosity, KOPTRI point
A12: Fig2b_Thermal lambda vs h-BN wt%: measured (laser flash), LN model at each film's open porosity; blanks = not measured (fragile)
A13: Fig2c_IR spot temperatures read from the infrared images (200 C stage), for the annotation of panel (c)
A14: Fig3a_Tensile tensile strength NP/HP and NP->HP change (%)
... A26: 4. Model constants reproduce Table 2 of the manuscript to +/-0.002 and the thermal RMSE of 0.027/0.030 W m-1 K-1.

Sheet Parameters
A1: Three-phase Lewis-Nielsen model parameters (edit yellow cells only)
A3: Name | B3: Value | C3: Unit | D3: Meaning / source
A4: eps_PI | B4: 3.5 | C4: - | D4: Dielectric constant of dense PMDA-ODA PI (manuscript Section 3.1)
A5: eps_BN | B5: 6 | C5: - | D5: Dielectric constant of h-BN (manuscript Section 1)
A6: eps_air | B6: 1 | C6: - | D6: Dielectric constant of air
A7: A_BN_eps | B7: 0.68 | C7: - | D7: h-BN shape factor, dielectric model (fitted, weakly determined; Table 1)
A8: phimax_BN_eps | B8: 0.99 | C8: - | D8: h-BN max. packing, dielectric model (boundary; Table 1)
A9: A_pore | B9: 0.08 | C9: - | D9: Pore shape factor (fitted; Table 1)
A10: phimax_pore | B10: 0.99 | C10: - | D10: Pore max. packing (boundary; Table 1)
A11: lam_PI | B11: 0.12 | C11: W m-1 K-1 | D11: Thermal conductivity of dense PI
A12: lam_BN_eff | B12: 6.81 | C12: W m-1 K-1 | D12: Effective h-BN conductivity (fitted, single parameter; Table 1)
A13: lam_air | B13: 0.026 | C13: W m-1 K-1 | D13: Thermal conductivity of air
A14: A_BN_lam | B14: 5.5 | C14: - | D14: h-BN shape factor, thermal model (fixed, literature; Table 1)
A15: phimax_BN_lam | B15: 0.6 | C15: - | D15: h-BN max. packing, thermal model (fixed, literature; Table 1)
... A17: rho_BN | B17: 2.29 | C17: g cm-3 | D17: Density of h-BN (Section 3.1)

Sheet Samples
A1: All ten films: measured data (blue) and model columns (formulas)
A3: h-BN (wt%) | B3: State | C3: phi_open (%) Hg intrusion | D3: phi_total (%) 1-rho/rho_solid | E3: rho (g cm-3) | F3: Cp (J g-1 K-1) | G3: alpha (mm2 s-1) | H3: lambda_exp (W m-1 K-1) | I3: eps_exp (100 kHz) | J3: Tensile (MPa) | K3: CTE_exp HP (ppm K-1) | L3: CTE_Turner (ppm K-1) | M3: CTE_ROM (ppm K-1) | N3: Thickness SEM (um) | O3: Delta t (%) | P3: phi_BN (solid vol frac) | Q3: rho_solid (g cm-3) | R3: eps_dense (model) | S3: eps_LN (model) | T3: Delta_eps (%) | U3: lam_dense (model) | V3: lam_LN (model) | W3: Delta_lam (%) | X3: Notes
A4: 0 | B4: NP | C4: 75.4 | D4: =IF(E4="","",100*(1-E4/Q4)) | I4: 1.757 | J4: 20.85 | N4: 167 | P4: =IF(A4=0,0,(A4/100/rho_BN)/((A4/100/rho_BN)+((1-A4/100)/rho_PI))) -> 0 | Q4: =1/((A4/100/rho_BN)+((1-A4/100)/rho_PI)) -> 1.42 | R4: =eps_PI*(1+A_BN_eps*((eps_BN/eps_PI-1)/(eps_BN/eps_PI+A_BN_eps))*P4)/(1-((eps_BN/eps_PI-1)/(eps_BN/eps_PI+A_BN_eps))*(1+((1-phimax_BN_eps)/phimax_BN_eps^2)*P4)*P4) -> 3.5 | S4: =R4*(1+A_pore*((eps_air/R4-1)/(eps_air/R4+A_pore))*(C4/100))/(1-((eps_air/R4-1)/(eps_air/R4+A_pore))*(1+((1-phimax_pore)/phimax_pore^2)*(C4/100))*(C4/100)) -> 1.2430251 | T4: =100*(S4-I4)/I4 -> -29.252985 | U4: =lam_PI*(1+A_BN_lam*((lam_BN_eff/lam_PI-1)/(lam_BN_eff/lam_PI+A_BN_lam))*P4)/(1-((lam_BN_eff/lam_PI-1)/(lam_BN_eff/lam_PI+A_BN_lam))*(1+((1-phimax_BN_lam)/phimax_BN_lam^2)*P4)*P4) -> 0.12 | V4: =U4*(1+A_pore*((lam_air/U4-1)/(lam_air/U4+A_pore))*(C4/100))/(1-((lam_air/U4-1)/(lam_air/U4+A_pore))*(1+((1-phimax_pore)/phimax_pore^2)*(C4/100))*(C4/100)) -> 0.033559599 | W4: =IF(H4="","",100*(V4-H4)/H4)
A5: 10 | B5: NP | C5: 91.4 | D5: =IF(E5="","",100*(1-E5/Q5)) | I5: 1.74 | J5: 14.86 | N5: 184 | P5: =IF(A5=0,0,(A5/100/rho_BN)/((A5/100/rho_BN)+((1-A5/100)/rho_PI))) -> 0.064457558 | Q5: =1/((A5/100/rho_BN)+((1-A5/100)/rho_PI)) -> 1.4760781 | R5: =eps_PI*(1+A_BN_eps*((eps_BN/eps_PI-1)/(eps_BN/eps_PI+A_BN_eps))*P5)/(1-((eps_BN/eps_PI-1)/(eps_BN/eps_PI+A_BN_eps))*(1+((1-phimax_BN_eps)/phimax_BN_eps^2)*P5)*P5) -> 3.6153335 | S5: =R5*(1+A_pore*((eps_air/R5-1)/(eps_air/R5+A_pore))*(C5/100))/(1-((eps_air/R5-1)/(eps_air/R5+A_pore))*(1+((1-phimax_pore)/phimax_pore^2)*(C5/100))*(C5/100)) -> 1.0723079 | T5: =100*(S5-I5)/I5 -> -38.373107 | U5: =lam_PI*(1+A_BN_lam*((lam_BN_eff/lam_PI-1)/(lam_BN_eff/lam_PI+A_BN_lam))*P5)/(1-((lam_BN_eff/lam_PI-1)/(lam_BN_eff/lam_PI+A_BN_lam))*(1+((1-phimax_BN_lam)/phimax_BN_lam^2)*P5)*P5) -> 0.16852505 | V5: =U5*(1+A_pore*((lam_air/U5-1)/(lam_air/U5+A_pore))*(C5/100))/(1-((lam_air/U5-1)/(lam_air/U5+A_pore))*(1+((1-phimax_pore)/phimax_pore^2)*(C5/100))*(C5/100)) -> 0.028645877 | W5: =IF(H5="","",100*(V5-H5)/H5) | X5: lambda not measured (film fragility)
A6: 30 | B6: NP | C6: 48.8 | D6: =IF(E6="","",100*(1-E6/Q6)) -> 79.846024 | E6: 0.323 | F6: 0.853 | G6: 0.23 | H6: 0.063 | I6: 1.659 | J6: 25.43 | N6: 91.5 | P6: =IF(A6=0,0,(A6/100/rho_BN)/((A6/100/rho_BN)+((1-A6/100)/rho_PI))) -> 0.20995564 | Q6: =1/((A6/100/rho_BN)+((1-A6/100)/rho_PI)) -> 1.6026614 | R6: =eps_PI*(1+A_BN_eps*((eps_BN/eps_PI-1)/(eps_BN/eps_PI+A_BN_eps))*P6)/(1-((eps_BN/eps_PI-1)/(eps_BN/eps_PI+A_BN_eps))*(1+((1-phimax_BN_eps)/phimax_BN_eps^2)*P6)*P6) -> 3.8934669 | S6: =R6*(1+A_pore*((eps_air/R6-1)/(eps_air/R6+A_pore))*(C6/100))/(1-((eps_air/R6-1)/(eps_air/R6+A_pore))*(1+((1-phimax_pore)/phimax_pore^2)*(C6/100))*(C6/100)) -> 1.7089728 | T6: =100*(S6-I6)/I6 -> 3.0122241 | U6: =lam_PI*(1+A_BN_lam*((lam_BN_eff/lam_PI-1)/(lam_BN_eff/lam_PI+A_BN_lam))*P6)/(1-((lam_BN_eff/lam_PI-1)/(lam_BN_eff/lam_PI+A_BN_lam))*(1+((1-phimax_BN_lam)/phimax_BN_lam^2)*P6)*P6) -> 0.3177981 | V6: =U6*(1+A_pore*((lam_air/U6-1)/(lam_air/U6+A_pore))*(C6/100))/(1-((lam_air/U6-1)/(lam_air/U6+A_pore))*(1+((1-phimax_pore)/phimax_pore^2)*(C6/100))*(C6/100)) -> 0.065399105 | W6: =IF(H6="","",100*(V6-H6)/H6) -> 3.8081028
A7: 50 | B7: NP | C7: 58.1 | D7: =IF(E7="","",100*(1-E7/Q7)) -> 70.621656 | E7: 0.515 | F7: 0.875 | G7: 0.202 | H7: 0.091 | I7: 1.407 | J7: 12.47 | N7: 84.1 | P7: =IF(A7=0,0,(A7/100/rho_BN)/((A7/100/rho_BN)+((1-A7/100)/rho_PI))) -> 0.38274933 | Q7: =1/((A7/100/rho_BN)+((1-A7/100)/rho_PI)) -> 1.7529919 | R7: =eps_PI*(1+A_BN_eps*((eps_BN/eps_PI-1)/(eps_BN/eps_PI+A_BN_eps))*P7)/(1-((eps_BN/eps_PI-1)/(eps_BN/eps_PI+A_BN_eps))*(1+((1-phimax_BN_eps)/phimax_BN_eps^2)*P7)*P7) -> 4.2601021 | S7: =R7*(1+A_pore*((eps_air/R7-1)/(eps_air/R7+A_pore))*(C7/100))/(1-((eps_air/R7-1)/(eps_air/R7+A_pore))*(1+((1-phimax_pore)/phimax_pore^2)*(C7/100))*(C7/100)) -> 1.5607533 | T7: =100*(S7-I7)/I7 -> 10.927741 | U7: =lam_PI*(1+A_BN_lam*((lam_BN_eff/lam_PI-1)/(lam_BN_eff/lam_PI+A_BN_lam))*P7)/(1-((lam_BN_eff/lam_PI-1)/(lam_BN_eff/lam_PI+A_BN_lam))*(1+((1-phimax_BN_lam)/phimax_BN_lam^2)*P7)*P7) -> 0.67698683 | V7: =U7*(1+A_pore*((lam_air/U7-1)/(lam_air/U7+A_pore))*(C7/100))/(1-((lam_air/U7-1)/(lam_air/U7+A_pore))*(1+((1-phimax_pore)/phimax_pore^2)*(C7/100))*(C7/100)) -> 0.073340391 | W7: =IF(H7="","",100*(V7-H7)/H7) -> -19.406163
A8: 70 | B8: NP | C8: 54.2 | D8: =IF(E8="","",100*(1-E8/Q8)) -> 72.808721 | E8: 0.526 | F8: 0.838 | G8: 0.693 | H8: 0.305 | I8: 1.278 | N8: 137 | P8: =IF(A8=0,0,(A8/100/rho_BN)/((A8/100/rho_BN)+((1-A8/100)/rho_PI))) -> 0.59131469 | Q8: =1/((A8/100/rho_BN)+((1-A8/100)/rho_PI)) -> 1.9344438 | R8: =eps_PI*(1+A_BN_eps*((eps_BN/eps_PI-1)/(eps_BN/eps_PI+A_BN_eps))*P8)/(1-((eps_BN/eps_PI-1)/(eps_BN/eps_PI+A_BN_eps))*(1+((1-phimax_BN_eps)/phimax_BN_eps^2)*P8)*P8) -> 4.7656031 | S8: =R8*(1+A_pore*((eps_air/R8-1)/(eps_air/R8+A_pore))*(C8/100))/(1-((eps_air/R8-1)/(eps_air/R8+A_pore))*(1+((1-phimax_pore)/phimax_pore^2)*(C8/100))*(C8/100)) -> 1.6905151 | T8: =100*(S8-I8)/I8 -> 32.278179 | U8: =lam_PI*(1+A_BN_lam*((lam_BN_eff/lam_PI-1)/(lam_BN_eff/lam_PI+A_BN_lam))*P8)/(1-((lam_BN_eff/lam_PI-1)/(lam_BN_eff/lam_PI+A_BN_lam))*(1+((1-phimax_BN_lam)/phimax_BN_lam^2)*P8)*P8) -> 3.833034 | V8: =U8*(1+A_pore*((lam_air/U8-1)/(lam_air/U8+A_pore))*(C8/100))/(1-((lam_air/U8-1)/(lam_air/U8+A_pore))*(1+((1-phimax_pore)/phimax_pore^2)*(C8/100))*(C8/100)) -> 0.26679524 | W8: =IF(H8="","",100*(V8-H8)/H8) -> -12.52615 | X8: tensile not tested (brittle)
A9: 0 | B9: HP | C9: 43.4 | D9: =IF(E9="","",100*(1-E9/Q9)) | I9: 2.178 | J9: 37.02 | K9: 41.92 | L9: 41.92 | M9: 41.92 | N9: 113 | O9: -32.3 | P9: =IF(A9=0,0,(A9/100/rho_BN)/((A9/100/rho_BN)+((1-A9/100)/rho_PI))) -> 0 | Q9: =1/((A9/100/rho_BN)+((1-A9/100)/rho_PI)) -> 1.42 | R9: =eps_PI*(1+A_BN_eps*((eps_BN/eps_PI-1)/(eps_BN/eps_PI+A_BN_eps))*P9)/(1-((eps_BN/eps_PI-1)/(eps_BN/eps_PI+A_BN_eps))*(1+((1-phimax_BN_eps)/phimax_BN_eps^2)*P9)*P9) -> 3.5 | S9: =R9*(1+A_pore*((eps_air/R9-1)/(eps_air/R9+A_pore))*(C9/100))/(1-((eps_air/R9-1)/(eps_air/R9+A_pore))*(1+((1-phimax_pore)/phimax_pore^2)*(C9/100))*(C9/100)) -> 1.7622551 | T9: =100*(S9-I9)/I9 -> -19.088381 | U9: =lam_PI*(1+A_BN_lam*((lam_BN_eff/lam_PI-1)/(lam_BN_eff/lam_PI+A_BN_lam))*P9)/(1-((lam_BN_eff/lam_PI-1)/(lam_BN_eff/lam_PI+A_BN_lam))*(1+((1-phimax_BN_lam)/phimax_BN_lam^2)*P9)*P9) -> 0.12 | V9: =U9*(1+A_pore*((lam_air/U9-1)/(lam_air/U9+A_pore))*(C9/100))/(1-((lam_air/U9-1)/(lam_air/U9+A_pore))*(1+((1-phimax_pore)/phimax_pore^2)*(C9/100))*(C9/100)) -> 0.050672867 | W9: =IF(H9="","",100*(V9-H9)/H9) | X9: lambda not measured (film fragility)
A10: 10 | B10: HP | C10: 29.8 | D10: =IF(E10="","",100*(1-E10/Q10)) -> 40.450304 | E10: 0.879 | F10: 0.903 | G10: 0.143 | H10: 0.114 | I10: 1.924 | J10: 17.74 | K10: 24.96 | L10: 9.69 | M10: 39.31 | N10: 134 | O10: -27.2 | P10: =IF(A10=0,0,(A10/100/rho_BN)/((A10/100/rho_BN)+((1-A10/100)/rho_PI))) -> 0.064457558 | Q10: =1/((A10/100/rho_BN)+((1-A10/100)/rho_PI)) -> 1.4760781 | R10: =eps_PI*(1+A_BN_eps*((eps_BN/eps_PI-1)/(eps_BN/eps_PI+A_BN_eps))*P10)/(1-((eps_BN/eps_PI-1)/(eps_BN/eps_PI+A_BN_eps))*(1+((1-phimax_BN_eps)/phimax_BN_eps^2)*P10)*P10) -> 3.6153335 | S10: =R10*(1+A_pore*((eps_air/R10-1)/(eps_air/R10+A_pore))*(C10/100))/(1-((eps_air/R10-1)/(eps_air/R10+A_pore))*(1+((1-phimax_pore)/phimax_pore^2)*(C10/100))*(C10/100)) -> 2.1417882 | T10: =100*(S10-I10)/I10 -> 11.319553 | U10: =lam_PI*(1+A_BN_lam*((lam_BN_eff/lam_PI-1)/(lam_BN_eff/lam_PI+A_BN_lam))*P10)/(1-((lam_BN_eff/lam_PI-1)/(lam_BN_eff/lam_PI+A_BN_lam))*(1+((1-phimax_BN_lam)/phimax_BN_lam^2)*P10)*P10) -> 0.16852505 | V10: =U10*(1+A_pore*((lam_air/U10-1)/(lam_air/U10+A_pore))*(C10/100))/(1-((lam_air/U10-1)/(lam_air/U10+A_pore))*(1+((1-phimax_pore)/phimax_pore^2)*(C10/100))*(C10/100)) -> 0.074084133 | W10: =IF(H10="","",100*(V10-H10)/H10) -> -35.013918
A11: 30 | B11: HP | C11: 67.2 | D11: =IF(E11="","",100*(1-E11/Q11)) -> 71.609724 | E11: 0.455 | F11: 0.863 | G11: 0.131 | H11: 0.051 | I11: 1.864 | J11: 38.15 | K11: 16.49 | L11: 4 | M11: 33.43 | N11: 57.2 | O11: -7 | P11: =IF(A11=0,0,(A11/100/rho_BN)/((A11/100/rho_BN)+((1-A11/100)/rho_PI))) -> 0.20995564 | Q11: =1/((A11/100/rho_BN)+((1-A11/100)/rho_PI)) -> 1.6026614 | R11: =eps_PI*(1+A_BN_eps*((eps_BN/eps_PI-1)/(eps_BN/eps_PI+A_BN_eps))*P11)/(1-((eps_BN/eps_PI-1)/(eps_BN/eps_PI+A_BN_eps))*(1+((1-phimax_BN_eps)/phimax_BN_eps^2)*P11)*P11) -> 3.8934669 | S11: =R11*(1+A_pore*((eps_air/R11-1)/(eps_air/R11+A_pore))*(C11/100))/(1-((eps_air/R11-1)/(eps_air/R11+A_pore))*(1+((1-phimax_pore)/phimax_pore^2)*(C11/100))*(C11/100)) -> 1.3766451 | T11: =100*(S11-I11)/I11 -> -26.14565 | U11: =lam_PI*(1+A_BN_lam*((lam_BN_eff/lam_PI-1)/(lam_BN_eff/lam_PI+A_BN_lam))*P11)/(1-((lam_BN_eff/lam_PI-1)/(lam_BN_eff/lam_PI+A_BN_lam))*(1+((1-phimax_BN_lam)/phimax_BN_lam^2)*P11)*P11) -> 0.3177981 | V11: =U11*(1+A_pore*((lam_air/U11-1)/(lam_air/U11+A_pore))*(C11/100))/(1-((lam_air/U11-1)/(lam_air/U11+A_pore))*(1+((1-phimax_pore)/phimax_pore^2)*(C11/100))*(C11/100)) -> 0.045637044 | W11: =IF(H11="","",100*(V11-H11)/H11) -> -10.5156 | X11: KOPTRI cross-check eps = 1.610 (ASTM D150)
A12: 50 | B12: HP | C12: 64.6 | D12: =IF(E12="","",100*(1-E12/Q12)) -> 61.323267 | E12: 0.678 | F12: 0.885 | G12: 0.147 | H12: 0.088 | I12: 1.829 | J12: 24.28 | K12: 13.06 | L12: 2.61 | M12: 26.45 | N12: 84.8 | O12: 0.8 | P12: =IF(A12=0,0,(A12/100/rho_BN)/((A12/100/rho_BN)+((1-A12/100)/rho_PI))) -> 0.38274933 | Q12: =1/((A12/100/rho_BN)+((1-A12/100)/rho_PI)) -> 1.7529919 | R12: =eps_PI*(1+A_BN_eps*((eps_BN/eps_PI-1)/(eps_BN/eps_PI+A_BN_eps))*P12)/(1-((eps_BN/eps_PI-1)/(eps_BN/eps_PI+A_BN_eps))*(1+((1-phimax_BN_eps)/phimax_BN_eps^2)*P12)*P12) -> 4.2601021 | S12: =R12*(1+A_pore*((eps_air/R12-1)/(eps_air/R12+A_pore))*(C12/100))/(1-((eps_air/R12-1)/(eps_air/R12+A_pore))*(1+((1-phimax_pore)/phimax_pore^2)*(C12/100))*(C12/100)) -> 1.4431204 | T12: =100*(S12-I12)/I12 -> -21.097846 | U12: =lam_PI*(1+A_BN_lam*((lam_BN_eff/lam_PI-1)/(lam_BN_eff/lam_PI+A_BN_lam))*P12)/(1-((lam_BN_eff/lam_PI-1)/(lam_BN_eff/lam_PI+A_BN_lam))*(1+((1-phimax_BN_lam)/phimax_BN_lam^2)*P12)*P12) -> 0.67698683 | V12: =U12*(1+A_pore*((lam_air/U12-1)/(lam_air/U12+A_pore))*(C12/100))/(1-((lam_air/U12-1)/(lam_air/U12+A_pore))*(1+((1-phimax_pore)/phimax_pore^2)*(C12/100))*(C12/100)) -> 0.062547504 | W12: =IF(H12="","",100*(V12-H12)/H12) -> -28.923291
A13: 70 | B13: HP | C13: 48.8 | D13: =IF(E13="","",100*(1-E13/Q13)) -> 72.136694 | E13: 0.539 | F13: 0.846 | G13: 0.613 | H13: 0.279 | I13: 1.622 | K13: 10.11 | L13: 1.98 | M13: 18.02 | N13: 115 | O13: -16.1 | P13: =IF(A13=0,0,(A13/100/rho_BN)/((A13/100/rho_BN)+((1-A13/100)/rho_PI))) -> 0.59131469 | Q13: =1/((A13/100/rho_BN)+((1-A13/100)/rho_PI)) -> 1.9344438 | R13: =eps_PI*(1+A_BN_eps*((eps_BN/eps_PI-1)/(eps_BN/eps_PI+A_BN_eps))*P13)/(1-((eps_BN/eps_PI-1)/(eps_BN/eps_PI+A_BN_eps))*(1+((1-phimax_BN_eps)/phimax_BN_eps^2)*P13)*P13) -> 4.7656031 | S13: =R13*(1+A_pore*((eps_air/R13-1)/(eps_air/R13+A_pore))*(C13/100))/(1-((eps_air/R13-1)/(eps_air/R13+A_pore))*(1+((1-phimax_pore)/phimax_pore^2)*(C13/100))*(C13/100)) -> 1.8221411 | T13: =100*(S13-I13)/I13 -> 12.339155 | U13: =lam_PI*(1+A_BN_lam*((lam_BN_eff/lam_PI-1)/(lam_BN_eff/lam_PI+A_BN_lam))*P13)/(1-((lam_BN_eff/lam_PI-1)/(lam_BN_eff/lam_PI+A_BN_lam))*(1+((1-phimax_BN_lam)/phimax_BN_lam^2)*P13)*P13) -> 3.833034 | V13: =U13*(1+A_pore*((lam_air/U13-1)/(lam_air/U13+A_pore))*(C13/100))/(1-((lam_air/U13-1)/(lam_air/U13+A_pore))*(1+((1-phimax_pore)/phimax_pore^2)*(C13/100))*(C13/100)) -> 0.32064909 | W13: =IF(H13="","",100*(V13-H13)/H13) -> 14.927989 | X13: tensile not tested (brittle)
A15: Sources: phi_open, rho, Cp, alpha, lambda = Table 3; eps = Table 2; tensile, CTE, Turner, ROM = Table 4; thickness = Fig. 1 SEM labels; Delta t = Section 4.1.
A16: RMSE check: | B16: eps NP | C16: =SQRT(SUMPRODUCT((S4:S8-I4:I8)^2)/5) -> 0.42574383 | D16: eps HP | E16: =SQRT(SUMPRODUCT((S9:S13-I9:I13)^2)/5) -> 0.35965258 | F16: lam NP | G16: =SQRT(SUMPRODUCT((V6:V8-H6:H8)^2)/3) -> 0.024339412 | H16: lam HP | I16: =SQRT(SUMPRODUCT((V10:V13-H10:H13)^2)/4) -> 0.031640615

Sheet Fig2a_Dielectric
A1: Figure 2a: dielectric constant (100 kHz) vs h-BN content
A3: h-BN (wt%) | B3: eps_NP_exp | C3: eps_HP_exp | D3: eps_LN_NP (model at NP open porosity) | E3: eps_LN_HP (model at HP open porosity) | F3: KOPTRI HP 30 wt% (not fitted) | G3: eps_air (reference line)
A4: 0 | B4: =Samples!I4 -> 1.757 | C4: =Samples!I9 -> 2.178 | D4: =Samples!S4 -> 1.2430251 | E4: =Samples!S9 -> 1.7622551 | G4: =eps_air -> 1
A5: 10 | B5: =Samples!I5 -> 1.74 | C5: =Samples!I10 -> 1.924 | D5: =Samples!S5 -> 1.0723079 | E5: =Samples!S10 -> 2.1417882 | G5: =eps_air -> 1
A6: 30 | B6: =Samples!I6 -> 1.659 | C6: =Samples!I11 -> 1.864 | D6: =Samples!S6 -> 1.7089728 | E6: =Samples!S11 -> 1.3766451 | F6: 1.61 | G6: =eps_air -> 1
A7: 50 | B7: =Samples!I7 -> 1.407 | C7: =Samples!I12 -> 1.829 | D7: =Samples!S7 -> 1.5607533 | E7: =Samples!S12 -> 1.4431204 | G7: =eps_air -> 1
A8: 70 | B8: =Samples!I8 -> 1.278 | C8: =Samples!I13 -> 1.622 | D8: =Samples!S8 -> 1.6905151 | E8: =Samples!S13 -> 1.8221411 | G8: =eps_air -> 1
A10: Plot: filled circles/squares = measured NP/HP (solid lines); open symbols + dashed lines = model; black diamond = KOPTRI; dotted line at eps = 1 (air).

Sheet Fig2b_Thermal
A1: Figure 2b: thermal conductivity vs h-BN content (W m-1 K-1)
A3: h-BN (wt%) | B3: lam_NP_exp | C3: lam_HP_exp | D3: lam_LN_NP (model at NP open porosity) | E3: lam_LN_HP (model at HP open porosity) | F3: NP measured? | G3: HP measured?
A4: 0 | B4: =IF(Samples!H4="","",Samples!H4) | C4: =IF(Samples!H9="","",Samples!H9) | D4: =Samples!V4 -> 0.033559599 | E4: =Samples!V9 -> 0.050672867 | F4: =IF(B4="","no (fragile)","yes") -> no (fragile) | G4: =IF(C4="","no (fragile)","yes") -> no (fragile)
A5: 10 | B5: =IF(Samples!H5="","",Samples!H5) | C5: =IF(Samples!H10="","",Samples!H10) -> 0.114 | D5: =Samples!V5 -> 0.028645877 | E5: =Samples!V10 -> 0.074084133 | F5: =IF(B5="","no (fragile)","yes") -> no (fragile) | G5: =IF(C5="","no (fragile)","yes") -> yes
A6: 30 | B6: =IF(Samples!H6="","",Samples!H6) -> 0.063 | C6: =IF(Samples!H11="","",Samples!H11) -> 0.051 | D6: =Samples!V6 -> 0.065399105 | E6: =Samples!V11 -> 0.045637044 | F6: =IF(B6="","no (fragile)","yes") -> yes | G6: =IF(C6="","no (fragile)","yes") -> yes
A7: 50 | B7: =IF(Samples!H7="","",Samples!H7) -> 0.091 | C7: =IF(Samples!H12="","",Samples!H12) -> 0.088 | D7: =Samples!V7 -> 0.073340391 | E7: =Samples!V12 -> 0.062547504 | F7: =IF(B7="","no (fragile)","yes") -> yes | G7: =IF(C7="","no (fragile)","yes") -> yes
A8: 70 | B8: =IF(Samples!H8="","",Samples!H8) -> 0.305 | C8: =IF(Samples!H13="","",Samples!H13) -> 0.279 | D8: =Samples!V8 -> 0.26679524 | E8: =Samples!V13 -> 0.32064909 | F8: =IF(B8="","no (fragile)","yes") -> yes | G8: =IF(C8="","no (fragile)","yes") -> yes
A10: Plot: filled symbols = measured; open symbols = model at each film's own porosity, joined by a vertical tie-line; crosses at compositions marked 'no'.

Sheet Fig2c_IR
A1: Figure 2c: infrared thermography spot temperatures (200 C stage; uncorrected radiometric values)
A3: h-BN (wt%) | B3: T_spot NP (C) | C3: T_spot HP (C) | D3: Label NP | E3: Label HP
A4: 0 | B4: 79.9 | C4: 76.4 | D4: =TEXT(ROUND(B4,0),"0")&" C" -> 80 C | E4: =TEXT(ROUND(C4,0),"0")&" C" -> 76 C
A5: 10 | B5: 144.3 | C5: 154.9 | D5: =TEXT(ROUND(B5,0),"0")&" C" -> 144 C | E5: =TEXT(ROUND(C5,0),"0")&" C" -> 155 C
A6: 30 | B6: 169 | C6: 196.1 | D6: =TEXT(ROUND(B6,0),"0")&" C" -> 169 C | E6: =TEXT(ROUND(C6,0),"0")&" C" -> 196 C
A7: 50 | B7: 179.8 | C7: 182.7 | D7: =TEXT(ROUND(B7,0),"0")&" C" -> 180 C | E7: =TEXT(ROUND(C7,0),"0")&" C" -> 183 C
A8: 70 | B8: 183.8 | C8: 192.2 | D8: =TEXT(ROUND(B8,0),"0")&" C" -> 184 C | E8: =TEXT(ROUND(C8,0),"0")&" C" -> 192 C
A10: Values read from the Sp1 annotation of each FLIR frame (Fig. 2c). Comparative only: emissivity not corrected. Equilibration time before imaging: [5] min (to be confirmed).

Sheet Fig3a_Tensile
A1: Figure 3a: tensile strength (MPa), n = 1 per bar
A3: h-BN (wt%) | B3: NP (MPa) | C3: HP (MPa) | D3: NP->HP change (%) | E3: Label
A4: 0 | B4: =IF(Samples!J4="","",Samples!J4) -> 20.85 | C4: =IF(Samples!J9="","",Samples!J9) -> 37.02 | D4: =IF(OR(B4="",C4=""),"",100*(C4-B4)/B4) -> 77.553957 | E4: =IF(D4="","not tested (too brittle)","+"&TEXT(D4,"0")&"%") -> +78%
A5: 10 | B5: =IF(Samples!J5="","",Samples!J5) -> 14.86 | C5: =IF(Samples!J10="","",Samples!J10) -> 17.74 | D5: =IF(OR(B5="",C5=""),"",100*(C5-B5)/B5) -> 19.380888 | E5: =IF(D5="","not tested (too brittle)","+"&TEXT(D5,"0")&"%") -> +19%
A6: 30 | B6: =IF(Samples!J6="","",Samples!J6) -> 25.43 | C6: =IF(Samples!J11="","",Samples!J11) -> 38.15 | D6: =IF(OR(B6="",C6=""),"",100*(C6-B6)/B6) -> 50.019662 | E6: =IF(D6="","not tested (too brittle)","+"&TEXT(D6,"0")&"%") -> +50%
A7: 50 | B7: =IF(Samples!J7="","",Samples!J7) -> 12.47 | C7: =IF(Samples!J12="","",Samples!J12) -> 24.28 | D7: =IF(OR(B7="",C7=""),"",100*(C7-B7)/B7) -> 94.707298 | E7: =IF(D7="","not tested (too brittle)","+"&TEXT(D7,"0")&"%") -> +95%
A8: 70 | B8: =IF(Samples!J8="","",Samples!J8) | C8: =IF(Samples!J13="","",Samples!J13) | D8: =IF(OR(B8="",C8=""),"",100*(C8-B8)/B8) | E8: =IF(D8="","not tested (too brittle)","+"&TEXT(D8,"0")&"%") -> not tested (too brittle)
A10: 70 wt%: draw a small baseline stub (not zero) and label 'not tested (too brittle)'.

Sheet Fig3b_CTE
A1: Figure 3b: CTE of HP films (ppm K-1) with Turner and rule-of-mixtures bounds
A3: h-BN (wt%) | B3: CTE_exp HP | C3: Turner (lower bound) | D3: ROM (upper bound) | E3: PCB window low | F3: PCB window high
A4: 0 | B4: =Samples!K9 -> 41.92 | C4: =Samples!L9 -> 41.92 | D4: =Samples!M9 -> 41.92 | E4: 3 | F4: 17
A5: 10 | B5: =Samples!K10 -> 24.96 | C5: =Samples!L10 -> 9.69 | D5: =Samples!M10 -> 39.31 | E5: 3 | F5: 17
A6: 30 | B6: =Samples!K11 -> 16.49 | C6: =Samples!L11 -> 4 | D6: =Samples!M11 -> 33.43 | E6: 3 | F6: 17
A7: 50 | B7: =Samples!K12 -> 13.06 | C7: =Samples!L12 -> 2.61 | D7: =Samples!M12 -> 26.45 | E7: 3 | F7: 17
A8: 70 | B8: =Samples!K13 -> 10.11 | C8: =Samples!L13 -> 1.98 | D8: =Samples!M13 -> 18.02 | E8: 3 | F8: 17
A10: Turner and ROM computed with alpha_PI = 41.92 ppm/K (measured, neat HP), E_PI = 3.5 GPa, E_BN = 200 GPa, alpha_BN = 1.5 ppm/K (Table 4). Shade 3-17 ppm/K as the PCB target zone; annotate 10.1 ppm/K at 70 wt%.

Sheet Fig4a_EpsMap
A1: Figure 4a: eps design map (three-phase LN model)
A2: helper rows: 3 = h-BN wt%, 4 = phi_BN, 5 = dense-composite property, 6 = B_pore. Grid from row 8: rows = porosity (%), columns = wt%.
A3: wt% -> | B3: 0 | C3: 2 | D3: 4 | E3: 6 | F3: 8 | G3: 10 | H3: 12 | I3: 14 | J3: 16 | K3: 18 | L3: 20 | M3: 22 | N3: 24 | O3: 26 | P3: 28 | Q3: 30 | R3: 32 | S3: 34 | T3: 36 | U3: 38 | V3: 40 | W3: 42 | X3: 44 | Y3: 46 | Z3: 48 | AA3: 50 | AB3: 52 | AC3: 54 | AD3: 56 | AE3: 58 | AF3: 60 | AG3: 62 | AH3: 64 | AI3: 66 | AJ3: 68 | AK3: 70
A4: phi_BN | B4: =IF(B$3=0,0,(B$3/100/rho_BN)/((B$3/100/rho_BN)+((1-B$3/100)/rho_PI))) -> 0 | C4: =IF(C$3=0,0,(C$3/100/rho_BN)/((C$3/100/rho_BN)+((1-C$3/100)/rho_PI))) -> 0.0124967 | D4: =IF(D$3=0,0,(D$3/100/rho_BN)/((D$3/100/rho_BN)+((1-D$3/100)/rho_PI))) -> 0.025186236 | E4: =IF(E$3=0,0,(E$3/100/rho_BN)/((E$3/100/rho_BN)+((1-E$3/100)/rho_PI))) -> 0.038073108 | F4: =IF(F$3=0,0,(F$3/100/rho_BN)/((F$3/100/rho_BN)+((1-F$3/100)/rho_PI))) -> 0.051161953 | G4: =IF(G$3=0,0,(G$3/100/rho_BN)/((G$3/100/rho_BN)+((1-G$3/100)/rho_PI))) -> 0.064457558 | H4: =IF(H$3=0,0,(H$3/100/rho_BN)/((H$3/100/rho_BN)+((1-H$3/100)/rho_PI))) -> 0.077964861 | I4: =IF(I$3=0,0,(I$3/100/rho_BN)/((I$3/100/rho_BN)+((1-I$3/100)/rho_PI))) -> 0.091688959 | ... AK4: =IF(AK$3=0,0,(AK$3/100/rho_BN)/((AK$3/100/rho_BN)+((1-AK$3/100)/rho_PI))) -> 0.59131469
A5: dense property | B5: =eps_PI*(1+A_BN_eps*((eps_BN/eps_PI-1)/(eps_BN/eps_PI+A_BN_eps))*B$4)/(1-((eps_BN/eps_PI-1)/(eps_BN/eps_PI+A_BN_eps))*(1+((1-phimax_BN_eps)/phimax_BN_eps^2)*B$4)*B$4) -> 3.5 | C5: =eps_PI*(1+A_BN_eps*((eps_BN/eps_PI-1)/(eps_BN/eps_PI+A_BN_eps))*C$4)/(1-((eps_BN/eps_PI-1)/(eps_BN/eps_PI+A_BN_eps))*(1+((1-phimax_BN_eps)/phimax_BN_eps^2)*C$4)*C$4) -> 3.5220051 | D5: =eps_PI*(1+A_BN_eps*((eps_BN/eps_PI-1)/(eps_BN/eps_PI+A_BN_eps))*D$4)/(1-((eps_BN/eps_PI-1)/(eps_BN/eps_PI+A_BN_eps))*(1+((1-phimax_BN_eps)/phimax_BN_eps^2)*D$4)*D$4) -> 3.5445225 | E5: =eps_PI*(1+A_BN_eps*((eps_BN/eps_PI-1)/(eps_BN/eps_PI+A_BN_eps))*E$4)/(1-((eps_BN/eps_PI-1)/(eps_BN/eps_PI+A_BN_eps))*(1+((1-phimax_BN_eps)/phimax_BN_eps^2)*E$4)*E$4) -> 3.5675702 | F5: =eps_PI*(1+A_BN_eps*((eps_BN/eps_PI-1)/(eps_BN/eps_PI+A_BN_eps))*F$4)/(1-((eps_BN/eps_PI-1)/(eps_BN/eps_PI+A_BN_eps))*(1+((1-phimax_BN_eps)/phimax_BN_eps^2)*F$4)*F$4) -> 3.5911672 | G5: =eps_PI*(1+A_BN_eps*((eps_BN/eps_PI-1)/(eps_BN/eps_PI+A_BN_eps))*G$4)/(1-((eps_BN/eps_PI-1)/(eps_BN/eps_PI+A_BN_eps))*(1+((1-phimax_BN_eps)/phimax_BN_eps^2)*G$4)*G$4) -> 3.6153335 | H5: =eps_PI*(1+A_BN_eps*((eps_BN/eps_PI-1)/(eps_BN/eps_PI+A_BN_eps))*H$4)/(1-((eps_BN/eps_PI-1)/(eps_BN/eps_PI+A_BN_eps))*(1+((1-phimax_BN_eps)/phimax_BN_eps^2)*H$4)*H$4) -> 3.6400899 | I5: =eps_PI*(1+A_BN_eps*((eps_BN/eps_PI-1)/(eps_BN/eps_PI+A_BN_eps))*I$4)/(1-((eps_BN/eps_PI-1)/(eps_BN/eps_PI+A_BN_eps))*(1+((1-phimax_BN_eps)/phimax_BN_eps^2)*I$4)*I$4) -> 3.6654583 | ... AK5: =eps_PI*(1+A_BN_eps*((eps_BN/eps_PI-1)/(eps_BN/eps_PI+A_BN_eps))*AK$4)/(1-((eps_BN/eps_PI-1)/(eps_BN/eps_PI+A_BN_eps))*(1+((1-phimax_BN_eps)/phimax_BN_eps^2)*AK$4)*AK$4) -> 4.7656031
A6: B_pore | B6: =(eps_air/B$5-1)/(eps_air/B$5+A_pore) -> -1.953125 | C6: =(eps_air/C$5-1)/(eps_air/C$5+A_pore) -> -1.9676104 | D6: =(eps_air/D$5-1)/(eps_air/D$5+A_pore) -> -1.9823919 | E6: =(eps_air/E$5-1)/(eps_air/E$5+A_pore) -> -1.9974786 | F6: =(eps_air/F$5-1)/(eps_air/F$5+A_pore) -> -2.0128801 | G6: =(eps_air/G$5-1)/(eps_air/G$5+A_pore) -> -2.0286064 | H6: =(eps_air/H$5-1)/(eps_air/H$5+A_pore) -> -2.0446679 | I6: =(eps_air/I$5-1)/(eps_air/I$5+A_pore) -> -2.0610754 | ... AK6: =(eps_air/AK$5-1)/(eps_air/AK$5+A_pore) -> -2.7262319
A8: porosity (%) \ wt% | B8: =B$3 -> 0 | C8: =C$3 -> 2 | D8: =D$3 -> 4 | E8: =E$3 -> 6 | F8: =F$3 -> 8 | G8: =G$3 -> 10 | H8: =H$3 -> 12 | I8: =I$3 -> 14 | ... AK8: =AK$3 -> 70 | AN8: Measured overlay (for symbols and NP->HP arrows)
A9: 0 | B9: =B$5*(1+A_pore*B$6*($A9/100))/(1-B$6*(1+((1-phimax_pore)/phimax_pore^2)*($A9/100))*($A9/100)) -> 3.5 | C9: =C$5*(1+A_pore*C$6*($A9/100))/(1-C$6*(1+((1-phimax_pore)/phimax_pore^2)*($A9/100))*($A9/100)) -> 3.5220051 | D9: =D$5*(1+A_pore*D$6*($A9/100))/(1-D$6*(1+((1-phimax_pore)/phimax_pore^2)*($A9/100))*($A9/100)) -> 3.5445225 | E9: =E$5*(1+A_pore*E$6*($A9/100))/(1-E$6*(1+((1-phimax_pore)/phimax_pore^2)*($A9/100))*($A9/100)) -> 3.5675702 | F9: =F$5*(1+A_pore*F$6*($A9/100))/(1-F$6*(1+((1-phimax_pore)/phimax_pore^2)*($A9/100))*($A9/100)) -> 3.5911672 | G9: =G$5*(1+A_pore*G$6*($A9/100))/(1-G$6*(1+((1-phimax_pore)/phimax_pore^2)*($A9/100))*($A9/100)) -> 3.6153335 | H9: =H$5*(1+A_pore*H$6*($A9/100))/(1-H$6*(1+((1-phimax_pore)/phimax_pore^2)*($A9/100))*($A9/100)) -> 3.6400899 | I9: =I$5*(1+A_pore*I$6*($A9/100))/(1-I$6*(1+((1-phimax_pore)/phimax_pore^2)*($A9/100))*($A9/100)) -> 3.6654583 | ... AK9: =AK$5*(1+A_pore*AK$6*($A9/100))/(1-AK$6*(1+((1-phimax_pore)/phimax_pore^2)*($A9/100))*($A9/100)) -> 4.7656031 | AN9: h-BN (wt%) | AO9: phi_open NP (%) | AP9: phi_open HP (%) | AQ9: arrow dx | AR9: arrow dy
A10: 1 | B10: =B$5*(1+A_pore*B$6*($A10/100))/(1-B$6*(1+((1-phimax_pore)/phimax_pore^2)*($A10/100))*($A10/100)) -> 3.4275795 | C10: =C$5*(1+A_pore*C$6*($A10/100))/(1-C$6*(1+((1-phimax_pore)/phimax_pore^2)*($A10/100))*($A10/100)) -> 3.4485993 | D10: =D$5*(1+A_pore*D$6*($A10/100))/(1-D$6*(1+((1-phimax_pore)/phimax_pore^2)*($A10/100))*($A10/100)) -> 3.4701031 | E10: =E$5*(1+A_pore*E$6*($A10/100))/(1-E$6*(1+((1-phimax_pore)/phimax_pore^2)*($A10/100))*($A10/100)) -> 3.492108 | F10: =F$5*(1+A_pore*F$6*($A10/100))/(1-F$6*(1+((1-phimax_pore)/phimax_pore^2)*($A10/100))*($A10/100)) -> 3.5146318 | G10: =G$5*(1+A_pore*G$6*($A10/100))/(1-G$6*(1+((1-phimax_pore)/phimax_pore^2)*($A10/100))*($A10/100)) -> 3.537693 | H10: =H$5*(1+A_pore*H$6*($A10/100))/(1-H$6*(1+((1-phimax_pore)/phimax_pore^2)*($A10/100))*($A10/100)) -> 3.5613112 | I10: =I$5*(1+A_pore*I$6*($A10/100))/(1-I$6*(1+((1-phimax_pore)/phimax_pore^2)*($A10/100))*($A10/100)) -> 3.5855069 | ... AK10: =AK$5*(1+A_pore*AK$6*($A10/100))/(1-AK$6*(1+((1-phimax_pore)/phimax_pore^2)*($A10/100))*($A10/100)) -> 4.6289992 | AN10: 0 | AO10: =Samples!C4 -> 75.4 | AP10: =Samples!C9 -> 43.4 | AQ10: 0 | AR10: =AP10-AO10 -> -32
A11: 2 | B11: =B$5*(1+A_pore*B$6*($A11/100))/(1-B$6*(1+((1-phimax_pore)/phimax_pore^2)*($A11/100))*($A11/100)) -> 3.357869 | C11: =C$5*(1+A_pore*C$6*($A11/100))/(1-C$6*(1+((1-phimax_pore)/phimax_pore^2)*($A11/100))*($A11/100)) -> 3.3779599 | D11: =D$5*(1+A_pore*D$6*($A11/100))/(1-D$6*(1+((1-phimax_pore)/phimax_pore^2)*($A11/100))*($A11/100)) -> 3.3985088 | E11: =E$5*(1+A_pore*E$6*($A11/100))/(1-E$6*(1+((1-phimax_pore)/phimax_pore^2)*($A11/100))*($A11/100)) -> 3.4195316 | F11: =F$5*(1+A_pore*F$6*($A11/100))/(1-F$6*(1+((1-phimax_pore)/phimax_pore^2)*($A11/100))*($A11/100)) -> 3.441045 | G11: =G$5*(1+A_pore*G$6*($A11/100))/(1-G$6*(1+((1-phimax_pore)/phimax_pore^2)*($A11/100))*($A11/100)) -> 3.4630663 | H11: =H$5*(1+A_pore*H$6*($A11/100))/(1-H$6*(1+((1-phimax_pore)/phimax_pore^2)*($A11/100))*($A11/100)) -> 3.4856139 | I11: =I$5*(1+A_pore*I$6*($A11/100))/(1-I$6*(1+((1-phimax_pore)/phimax_pore^2)*($A11/100))*($A11/100)) -> 3.5087069 | ... AK11: =AK$5*(1+A_pore*AK$6*($A11/100))/(1-AK$6*(1+((1-phimax_pore)/phimax_pore^2)*($A11/100))*($A11/100)) -> 4.4994355 | AN11: 10 | AO11: =Samples!C5 -> 91.4 | AP11: =Samples!C10 -> 29.8 | AQ11: 0 | AR11: =AP11-AO11 -> -61.6
A12: 3 | B12: =B$5*(1+A_pore*B$6*($A12/100))/(1-B$6*(1+((1-phimax_pore)/phimax_pore^2)*($A12/100))*($A12/100)) -> 3.2907192 | C12: =C$5*(1+A_pore*C$6*($A12/100))/(1-C$6*(1+((1-phimax_pore)/phimax_pore^2)*($A12/100))*($A12/100)) -> 3.3099337 | D12: =D$5*(1+A_pore*D$6*($A12/100))/(1-D$6*(1+((1-phimax_pore)/phimax_pore^2)*($A12/100))*($A12/100)) -> 3.3295819 | E12: =E$5*(1+A_pore*E$6*($A12/100))/(1-E$6*(1+((1-phimax_pore)/phimax_pore^2)*($A12/100))*($A12/100)) -> 3.3496787 | F12: =F$5*(1+A_pore*F$6*($A12/100))/(1-F$6*(1+((1-phimax_pore)/phimax_pore^2)*($A12/100))*($A12/100)) -> 3.3702397 | G12: =G$5*(1+A_pore*G$6*($A12/100))/(1-G$6*(1+((1-phimax_pore)/phimax_pore^2)*($A12/100))*($A12/100)) -> 3.3912812 | H12: =H$5*(1+A_pore*H$6*($A12/100))/(1-H$6*(1+((1-phimax_pore)/phimax_pore^2)*($A12/100))*($A12/100)) -> 3.4128206 | I12: =I$5*(1+A_pore*I$6*($A12/100))/(1-I$6*(1+((1-phimax_pore)/phimax_pore^2)*($A12/100))*($A12/100)) -> 3.4348757 | ... AK12: =AK$5*(1+A_pore*AK$6*($A12/100))/(1-AK$6*(1+((1-phimax_pore)/phimax_pore^2)*($A12/100))*($A12/100)) -> 4.3763815 | AN12: 30 | AO12: =Samples!C6 -> 48.8 | AP12: =Samples!C11 -> 67.2 | AQ12: 0 | AR12: =AP12-AO12 -> 18.4
A13: 4 | B13: =B$5*(1+A_pore*B$6*($A13/100))/(1-B$6*(1+((1-phimax_pore)/phimax_pore^2)*($A13/100))*($A13/100)) -> 3.2259916 | C13: =C$5*(1+A_pore*C$6*($A13/100))/(1-C$6*(1+((1-phimax_pore)/phimax_pore^2)*($A13/100))*($A13/100)) -> 3.2443782 | D13: =D$5*(1+A_pore*D$6*($A13/100))/(1-D$6*(1+((1-phimax_pore)/phimax_pore^2)*($A13/100))*($A13/100)) -> 3.2631759 | E13: =E$5*(1+A_pore*E$6*($A13/100))/(1-E$6*(1+((1-phimax_pore)/phimax_pore^2)*($A13/100))*($A13/100)) -> 3.2823986 | F13: =F$5*(1+A_pore*F$6*($A13/100))/(1-F$6*(1+((1-phimax_pore)/phimax_pore^2)*($A13/100))*($A13/100)) -> 3.3020611 | G13: =G$5*(1+A_pore*G$6*($A13/100))/(1-G$6*(1+((1-phimax_pore)/phimax_pore^2)*($A13/100))*($A13/100)) -> 3.3221787 | H13: =H$5*(1+A_pore*H$6*($A13/100))/(1-H$6*(1+((1-phimax_pore)/phimax_pore^2)*($A13/100))*($A13/100)) -> 3.3427674 | I13: =I$5*(1+A_pore*I$6*($A13/100))/(1-I$6*(1+((1-phimax_pore)/phimax_pore^2)*($A13/100))*($A13/100)) -> 3.3638443 | ... AK13: =AK$5*(1+A_pore*AK$6*($A13/100))/(1-AK$6*(1+((1-phimax_pore)/phimax_pore^2)*($A13/100))*($A13/100)) -> 4.2593587 | AN13: 50 | AO13: =Samples!C7 -> 58.1 | AP13: =Samples!C12 -> 64.6 | AQ13: 0 | AR13: =AP13-AO13 -> 6.5
A14: 5 | B14: =B$5*(1+A_pore*B$6*($A14/100))/(1-B$6*(1+((1-phimax_pore)/phimax_pore^2)*($A14/100))*($A14/100)) -> 3.1635575 | C14: =C$5*(1+A_pore*C$6*($A14/100))/(1-C$6*(1+((1-phimax_pore)/phimax_pore^2)*($A14/100))*($A14/100)) -> 3.1811614 | D14: =D$5*(1+A_pore*D$6*($A14/100))/(1-D$6*(1+((1-phimax_pore)/phimax_pore^2)*($A14/100))*($A14/100)) -> 3.1991552 | E14: =E$5*(1+A_pore*E$6*($A14/100))/(1-E$6*(1+((1-phimax_pore)/phimax_pore^2)*($A14/100))*($A14/100)) -> 3.2175521 | F14: =F$5*(1+A_pore*F$6*($A14/100))/(1-F$6*(1+((1-phimax_pore)/phimax_pore^2)*($A14/100))*($A14/100)) -> 3.2363659 | G14: =G$5*(1+A_pore*G$6*($A14/100))/(1-G$6*(1+((1-phimax_pore)/phimax_pore^2)*($A14/100))*($A14/100)) -> 3.255611 | H14: =H$5*(1+A_pore*H$6*($A14/100))/(1-H$6*(1+((1-phimax_pore)/phimax_pore^2)*($A14/100))*($A14/100)) -> 3.2753026 | I14: =I$5*(1+A_pore*I$6*($A14/100))/(1-I$6*(1+((1-phimax_pore)/phimax_pore^2)*($A14/100))*($A14/100)) -> 3.2954567 | ... AK14: =AK$5*(1+A_pore*AK$6*($A14/100))/(1-AK$6*(1+((1-phimax_pore)/phimax_pore^2)*($A14/100))*($A14/100)) -> 4.1479345 | AN14: 70 | AO14: =Samples!C8 -> 54.2 | AP14: =Samples!C13 -> 48.8 | AQ14: 0 | AR14: =AP14-AO14 -> -5.4
A15: 6 | B15: =B$5*(1+A_pore*B$6*($A15/100))/(1-B$6*(1+((1-phimax_pore)/phimax_pore^2)*($A15/100))*($A15/100)) -> 3.1032972 | C15: =C$5*(1+A_pore*C$6*($A15/100))/(1-C$6*(1+((1-phimax_pore)/phimax_pore^2)*($A15/100))*($A15/100)) -> 3.1201603 | D15: =D$5*(1+A_pore*D$6*($A15/100))/(1-D$6*(1+((1-phimax_pore)/phimax_pore^2)*($A15/100))*($A15/100)) -> 3.1373936 | E15: =E$5*(1+A_pore*E$6*($A15/100))/(1-E$6*(1+((1-phimax_pore)/phimax_pore^2)*($A15/100))*($A15/100)) -> 3.1550094 | F15: =F$5*(1+A_pore*F$6*($A15/100))/(1-F$6*(1+((1-phimax_pore)/phimax_pore^2)*($A15/100))*($A15/100)) -> 3.1730208 | G15: =G$5*(1+A_pore*G$6*($A15/100))/(1-G$6*(1+((1-phimax_pore)/phimax_pore^2)*($A15/100))*($A15/100)) -> 3.1914413 | H15: =H$5*(1+A_pore*H$6*($A15/100))/(1-H$6*(1+((1-phimax_pore)/phimax_pore^2)*($A15/100))*($A15/100)) -> 3.2102854 | I15: =I$5*(1+A_pore*I$6*($A15/100))/(1-I$6*(1+((1-phimax_pore)/phimax_pore^2)*($A15/100))*($A15/100)) -> 3.2295678 | ... AK15: =AK$5*(1+A_pore*AK$6*($A15/100))/(1-AK$6*(1+((1-phimax_pore)/phimax_pore^2)*($A15/100))*($A15/100)) -> 4.0417167
A16: 7 | B16: =B$5*(1+A_pore*B$6*($A16/100))/(1-B$6*(1+((1-phimax_pore)/phimax_pore^2)*($A16/100))*($A16/100)) -> 3.0450992 | C16: =C$5*(1+A_pore*C$6*($A16/100))/(1-C$6*(1+((1-phimax_pore)/phimax_pore^2)*($A16/100))*($A16/100)) -> 3.0612606 | D16: =D$5*(1+A_pore*D$6*($A16/100))/(1-D$6*(1+((1-phimax_pore)/phimax_pore^2)*($A16/100))*($A16/100)) -> 3.0777736 | E16: =E$5*(1+A_pore*E$6*($A16/100))/(1-E$6*(1+((1-phimax_pore)/phimax_pore^2)*($A16/100))*($A16/100)) -> 3.0946499 | F16: =F$5*(1+A_pore*F$6*($A16/100))/(1-F$6*(1+((1-phimax_pore)/phimax_pore^2)*($A16/100))*($A16/100)) -> 3.111902 | G16: =G$5*(1+A_pore*G$6*($A16/100))/(1-G$6*(1+((1-phimax_pore)/phimax_pore^2)*($A16/100))*($A16/100)) -> 3.1295425 | H16: =H$5*(1+A_pore*H$6*($A16/100))/(1-H$6*(1+((1-phimax_pore)/phimax_pore^2)*($A16/100))*($A16/100)) -> 3.147585 | I16: =I$5*(1+A_pore*I$6*($A16/100))/(1-I$6*(1+((1-phimax_pore)/phimax_pore^2)*($A16/100))*($A16/100)) -> 3.1660434 | ... AK16: =AK$5*(1+A_pore*AK$6*($A16/100))/(1-AK$6*(1+((1-phimax_pore)/phimax_pore^2)*($A16/100))*($A16/100)) -> 3.9403487 | AN16: Faded bands in the figure: porosity > 91 % and < 30 % (outside the measured range).
A17: 8 | B17: =B$5*(1+A_pore*B$6*($A17/100))/(1-B$6*(1+((1-phimax_pore)/phimax_pore^2)*($A17/100))*($A17/100)) -> 2.9888595 | C17: =C$5*(1+A_pore*C$6*($A17/100))/(1-C$6*(1+((1-phimax_pore)/phimax_pore^2)*($A17/100))*($A17/100)) -> 3.0043555 | D17: =D$5*(1+A_pore*D$6*($A17/100))/(1-D$6*(1+((1-phimax_pore)/phimax_pore^2)*($A17/100))*($A17/100)) -> 3.0201857 | E17: =E$5*(1+A_pore*E$6*($A17/100))/(1-E$6*(1+((1-phimax_pore)/phimax_pore^2)*($A17/100))*($A17/100)) -> 3.0363614 | F17: =F$5*(1+A_pore*F$6*($A17/100))/(1-F$6*(1+((1-phimax_pore)/phimax_pore^2)*($A17/100))*($A17/100)) -> 3.0528942 | G17: =G$5*(1+A_pore*G$6*($A17/100))/(1-G$6*(1+((1-phimax_pore)/phimax_pore^2)*($A17/100))*($A17/100)) -> 3.069796 | H17: =H$5*(1+A_pore*H$6*($A17/100))/(1-H$6*(1+((1-phimax_pore)/phimax_pore^2)*($A17/100))*($A17/100)) -> 3.0870797 | I17: =I$5*(1+A_pore*I$6*($A17/100))/(1-I$6*(1+((1-phimax_pore)/phimax_pore^2)*($A17/100))*($A17/100)) -> 3.1047585 | ... AK17: =AK$5*(1+A_pore*AK$6*($A17/100))/(1-AK$6*(1+((1-phimax_pore)/phimax_pore^2)*($A17/100))*($A17/100)) -> 3.843506 | AN17: Suggested contour levels: eps 1.5, 1.8, 2.0; lambda 0.05, 0.12, 0.20 W m-1 K-1.
A18: 9 | B18: =B$5*(1+A_pore*B$6*($A18/100))/(1-B$6*(1+((1-phimax_pore)/phimax_pore^2)*($A18/100))*($A18/100)) -> 2.9344809 | C18: =C$5*(1+A_pore*C$6*($A18/100))/(1-C$6*(1+((1-phimax_pore)/phimax_pore^2)*($A18/100))*($A18/100)) -> 2.9493454 | D18: =D$5*(1+A_pore*D$6*($A18/100))/(1-D$6*(1+((1-phimax_pore)/phimax_pore^2)*($A18/100))*($A18/100)) -> 2.964528 | E18: =E$5*(1+A_pore*E$6*($A18/100))/(1-E$6*(1+((1-phimax_pore)/phimax_pore^2)*($A18/100))*($A18/100)) -> 2.9800392 | F18: =F$5*(1+A_pore*F$6*($A18/100))/(1-F$6*(1+((1-phimax_pore)/phimax_pore^2)*($A18/100))*($A18/100)) -> 2.9958899 | G18: =G$5*(1+A_pore*G$6*($A18/100))/(1-G$6*(1+((1-phimax_pore)/phimax_pore^2)*($A18/100))*($A18/100)) -> 3.0120917 | H18: =H$5*(1+A_pore*H$6*($A18/100))/(1-H$6*(1+((1-phimax_pore)/phimax_pore^2)*($A18/100))*($A18/100)) -> 3.0286564 | I18: =I$5*(1+A_pore*I$6*($A18/100))/(1-I$6*(1+((1-phimax_pore)/phimax_pore^2)*($A18/100))*($A18/100)) -> 3.0455967 | ... AK18: =AK$5*(1+A_pore*AK$6*($A18/100))/(1-AK$6*(1+((1-phimax_pore)/phimax_pore^2)*($A18/100))*($A18/100)) -> 3.7508923
A19: 10 | B19: =B$5*(1+A_pore*B$6*($A19/100))/(1-B$6*(1+((1-phimax_pore)/phimax_pore^2)*($A19/100))*($A19/100)) -> 2.8818725 | C19: =C$5*(1+A_pore*C$6*($A19/100))/(1-C$6*(1+((1-phimax_pore)/phimax_pore^2)*($A19/100))*($A19/100)) -> 2.8961373 | D19: =D$5*(1+A_pore*D$6*($A19/100))/(1-D$6*(1+((1-phimax_pore)/phimax_pore^2)*($A19/100))*($A19/100)) -> 2.9107049 | E19: =E$5*(1+A_pore*E$6*($A19/100))/(1-E$6*(1+((1-phimax_pore)/phimax_pore^2)*($A19/100))*($A19/100)) -> 2.9255854 | F19: =F$5*(1+A_pore*F$6*($A19/100))/(1-F$6*(1+((1-phimax_pore)/phimax_pore^2)*($A19/100))*($A19/100)) -> 2.940789 | G19: =G$5*(1+A_pore*G$6*($A19/100))/(1-G$6*(1+((1-phimax_pore)/phimax_pore^2)*($A19/100))*($A19/100)) -> 2.9563266 | H19: =H$5*(1+A_pore*H$6*($A19/100))/(1-H$6*(1+((1-phimax_pore)/phimax_pore^2)*($A19/100))*($A19/100)) -> 2.9722095 | I19: =I$5*(1+A_pore*I$6*($A19/100))/(1-I$6*(1+((1-phimax_pore)/phimax_pore^2)*($A19/100))*($A19/100)) -> 2.9884496 | ... AK19: =AK$5*(1+A_pore*AK$6*($A19/100))/(1-AK$6*(1+((1-phimax_pore)/phimax_pore^2)*($A19/100))*($A19/100)) -> 3.6622366
A20: 11 | B20: =B$5*(1+A_pore*B$6*($A20/100))/(1-B$6*(1+((1-phimax_pore)/phimax_pore^2)*($A20/100))*($A20/100)) -> 2.8309494 | C20: =C$5*(1+A_pore*C$6*($A20/100))/(1-C$6*(1+((1-phimax_pore)/phimax_pore^2)*($A20/100))*($A20/100)) -> 2.8446441 | D20: =D$5*(1+A_pore*D$6*($A20/100))/(1-D$6*(1+((1-phimax_pore)/phimax_pore^2)*($A20/100))*($A20/100)) -> 2.8586273 | E20: =E$5*(1+A_pore*E$6*($A20/100))/(1-E$6*(1+((1-phimax_pore)/phimax_pore^2)*($A20/100))*($A20/100)) -> 2.8729086 | F20: =F$5*(1+A_pore*F$6*($A20/100))/(1-F$6*(1+((1-phimax_pore)/phimax_pore^2)*($A20/100))*($A20/100)) -> 2.8874976 | G20: =G$5*(1+A_pore*G$6*($A20/100))/(1-G$6*(1+((1-phimax_pore)/phimax_pore^2)*($A20/100))*($A20/100)) -> 2.9024046 | H20: =H$5*(1+A_pore*H$6*($A20/100))/(1-H$6*(1+((1-phimax_pore)/phimax_pore^2)*($A20/100))*($A20/100)) -> 2.9176403 | I20: =I$5*(1+A_pore*I$6*($A20/100))/(1-I$6*(1+((1-phimax_pore)/phimax_pore^2)*($A20/100))*($A20/100)) -> 2.9332161 | ... AK20: =AK$5*(1+A_pore*AK$6*($A20/100))/(1-AK$6*(1+((1-phimax_pore)/phimax_pore^2)*($A20/100))*($A20/100)) -> 3.5772906
A21: 12 | B21: =B$5*(1+A_pore*B$6*($A21/100))/(1-B$6*(1+((1-phimax_pore)/phimax_pore^2)*($A21/100))*($A21/100)) -> 2.7816318 | C21: =C$5*(1+A_pore*C$6*($A21/100))/(1-C$6*(1+((1-phimax_pore)/phimax_pore^2)*($A21/100))*($A21/100)) -> 2.7947842 | D21: =D$5*(1+A_pore*D$6*($A21/100))/(1-D$6*(1+((1-phimax_pore)/phimax_pore^2)*($A21/100))*($A21/100)) -> 2.8082117 | E21: =E$5*(1+A_pore*E$6*($A21/100))/(1-E$6*(1+((1-phimax_pore)/phimax_pore^2)*($A21/100))*($A21/100)) -> 2.8219233 | F21: =F$5*(1+A_pore*F$6*($A21/100))/(1-F$6*(1+((1-phimax_pore)/phimax_pore^2)*($A21/100))*($A21/100)) -> 2.8359281 | G21: =G$5*(1+A_pore*G$6*($A21/100))/(1-G$6*(1+((1-phimax_pore)/phimax_pore^2)*($A21/100))*($A21/100)) -> 2.8502359 | H21: =H$5*(1+A_pore*H$6*($A21/100))/(1-H$6*(1+((1-phimax_pore)/phimax_pore^2)*($A21/100))*($A21/100)) -> 2.8648569 | I21: =I$5*(1+A_pore*I$6*($A21/100))/(1-I$6*(1+((1-phimax_pore)/phimax_pore^2)*($A21/100))*($A21/100)) -> 2.8798017 | ... AK21: =AK$5*(1+A_pore*AK$6*($A21/100))/(1-AK$6*(1+((1-phimax_pore)/phimax_pore^2)*($A21/100))*($A21/100)) -> 3.4958263
A22: 13 | B22: =B$5*(1+A_pore*B$6*($A22/100))/(1-B$6*(1+((1-phimax_pore)/phimax_pore^2)*($A22/100))*($A22/100)) -> 2.7338452 | C22: =C$5*(1+A_pore*C$6*($A22/100))/(1-C$6*(1+((1-phimax_pore)/phimax_pore^2)*($A22/100))*($A22/100)) -> 2.7464813 | D22: =D$5*(1+A_pore*D$6*($A22/100))/(1-D$6*(1+((1-phimax_pore)/phimax_pore^2)*($A22/100))*($A22/100)) -> 2.7593799 | E22: =E$5*(1+A_pore*E$6*($A22/100))/(1-E$6*(1+((1-phimax_pore)/phimax_pore^2)*($A22/100))*($A22/100)) -> 2.7725493 | F22: =F$5*(1+A_pore*F$6*($A22/100))/(1-F$6*(1+((1-phimax_pore)/phimax_pore^2)*($A22/100))*($A22/100)) -> 2.7859984 | G22: =G$5*(1+A_pore*G$6*($A22/100))/(1-G$6*(1+((1-phimax_pore)/phimax_pore^2)*($A22/100))*($A22/100)) -> 2.7997364 | H22: =H$5*(1+A_pore*H$6*($A22/100))/(1-H$6*(1+((1-phimax_pore)/phimax_pore^2)*($A22/100))*($A22/100)) -> 2.8137729 | I22: =I$5*(1+A_pore*I$6*($A22/100))/(1-I$6*(1+((1-phimax_pore)/phimax_pore^2)*($A22/100))*($A22/100)) -> 2.828118 | ... AK22: =AK$5*(1+A_pore*AK$6*($A22/100))/(1-AK$6*(1+((1-phimax_pore)/phimax_pore^2)*($A22/100))*($A22/100)) -> 3.417634
A23: 14 | B23: =B$5*(1+A_pore*B$6*($A23/100))/(1-B$6*(1+((1-phimax_pore)/phimax_pore^2)*($A23/100))*($A23/100)) -> 2.6875192 | C23: =C$5*(1+A_pore*C$6*($A23/100))/(1-C$6*(1+((1-phimax_pore)/phimax_pore^2)*($A23/100))*($A23/100)) -> 2.6996635 | D23: =D$5*(1+A_pore*D$6*($A23/100))/(1-D$6*(1+((1-phimax_pore)/phimax_pore^2)*($A23/100))*($A23/100)) -> 2.7120583 | E23: =E$5*(1+A_pore*E$6*($A23/100))/(1-E$6*(1+((1-phimax_pore)/phimax_pore^2)*($A23/100))*($A23/100)) -> 2.7247115 | F23: =F$5*(1+A_pore*F$6*($A23/100))/(1-F$6*(1+((1-phimax_pore)/phimax_pore^2)*($A23/100))*($A23/100)) -> 2.7376316 | G23: =G$5*(1+A_pore*G$6*($A23/100))/(1-G$6*(1+((1-phimax_pore)/phimax_pore^2)*($A23/100))*($A23/100)) -> 2.7508273 | H23: =H$5*(1+A_pore*H$6*($A23/100))/(1-H$6*(1+((1-phimax_pore)/phimax_pore^2)*($A23/100))*($A23/100)) -> 2.7643077 | I23: =I$5*(1+A_pore*I$6*($A23/100))/(1-I$6*(1+((1-phimax_pore)/phimax_pore^2)*($A23/100))*($A23/100)) -> 2.7780824 | ... AK23: =AK$5*(1+A_pore*AK$6*($A23/100))/(1-AK$6*(1+((1-phimax_pore)/phimax_pore^2)*($A23/100))*($A23/100)) -> 3.3425207
A24: 15 | B24: =B$5*(1+A_pore*B$6*($A24/100))/(1-B$6*(1+((1-phimax_pore)/phimax_pore^2)*($A24/100))*($A24/100)) -> 2.6425881 | C24: =C$5*(1+A_pore*C$6*($A24/100))/(1-C$6*(1+((1-phimax_pore)/phimax_pore^2)*($A24/100))*($A24/100)) -> 2.6542635 | D24: =D$5*(1+A_pore*D$6*($A24/100))/(1-D$6*(1+((1-phimax_pore)/phimax_pore^2)*($A24/100))*($A24/100)) -> 2.6661781 | E24: =E$5*(1+A_pore*E$6*($A24/100))/(1-E$6*(1+((1-phimax_pore)/phimax_pore^2)*($A24/100))*($A24/100)) -> 2.6783394 | F24: =F$5*(1+A_pore*F$6*($A24/100))/(1-F$6*(1+((1-phimax_pore)/phimax_pore^2)*($A24/100))*($A24/100)) -> 2.6907555 | G24: =G$5*(1+A_pore*G$6*($A24/100))/(1-G$6*(1+((1-phimax_pore)/phimax_pore^2)*($A24/100))*($A24/100)) -> 2.7034347 | H24: =H$5*(1+A_pore*H$6*($A24/100))/(1-H$6*(1+((1-phimax_pore)/phimax_pore^2)*($A24/100))*($A24/100)) -> 2.7163856 | I24: =I$5*(1+A_pore*I$6*($A24/100))/(1-I$6*(1+((1-phimax_pore)/phimax_pore^2)*($A24/100))*($A24/100)) -> 2.7296173 | ... AK24: =AK$5*(1+A_pore*AK$6*($A24/100))/(1-AK$6*(1+((1-phimax_pore)/phimax_pore^2)*($A24/100))*($A24/100)) -> 3.270308
A25: 16 | B25: =B$5*(1+A_pore*B$6*($A25/100))/(1-B$6*(1+((1-phimax_pore)/phimax_pore^2)*($A25/100))*($A25/100)) -> 2.5989898 | C25: =C$5*(1+A_pore*C$6*($A25/100))/(1-C$6*(1+((1-phimax_pore)/phimax_pore^2)*($A25/100))*($A25/100)) -> 2.6102178 | D25: =D$5*(1+A_pore*D$6*($A25/100))/(1-D$6*(1+((1-phimax_pore)/phimax_pore^2)*($A25/100))*($A25/100)) -> 2.6216743 | E25: =E$5*(1+A_pore*E$6*($A25/100))/(1-E$6*(1+((1-phimax_pore)/phimax_pore^2)*($A25/100))*($A25/100)) -> 2.6333666 | F25: =F$5*(1+A_pore*F$6*($A25/100))/(1-F$6*(1+((1-phimax_pore)/phimax_pore^2)*($A25/100))*($A25/100)) -> 2.6453023 | G25: =G$5*(1+A_pore*G$6*($A25/100))/(1-G$6*(1+((1-phimax_pore)/phimax_pore^2)*($A25/100))*($A25/100)) -> 2.6574891 | H25: =H$5*(1+A_pore*H$6*($A25/100))/(1-H$6*(1+((1-phimax_pore)/phimax_pore^2)*($A25/100))*($A25/100)) -> 2.6699354 | I25: =I$5*(1+A_pore*I$6*($A25/100))/(1-I$6*(1+((1-phimax_pore)/phimax_pore^2)*($A25/100))*($A25/100)) -> 2.6826498 | ... AK25: =AK$5*(1+A_pore*AK$6*($A25/100))/(1-AK$6*(1+((1-phimax_pore)/phimax_pore^2)*($A25/100))*($A25/100)) -> 3.2008311
A26: 17 | B26: =B$5*(1+A_pore*B$6*($A26/100))/(1-B$6*(1+((1-phimax_pore)/phimax_pore^2)*($A26/100))*($A26/100)) -> 2.5566659 | C26: =C$5*(1+A_pore*C$6*($A26/100))/(1-C$6*(1+((1-phimax_pore)/phimax_pore^2)*($A26/100))*($A26/100)) -> 2.5674668 | D26: =D$5*(1+A_pore*D$6*($A26/100))/(1-D$6*(1+((1-phimax_pore)/phimax_pore^2)*($A26/100))*($A26/100)) -> 2.5784861 | E26: =E$5*(1+A_pore*E$6*($A26/100))/(1-E$6*(1+((1-phimax_pore)/phimax_pore^2)*($A26/100))*($A26/100)) -> 2.5897309 | F26: =F$5*(1+A_pore*F$6*($A26/100))/(1-F$6*(1+((1-phimax_pore)/phimax_pore^2)*($A26/100))*($A26/100)) -> 2.6012081 | G26: =G$5*(1+A_pore*G$6*($A26/100))/(1-G$6*(1+((1-phimax_pore)/phimax_pore^2)*($A26/100))*($A26/100)) -> 2.6129254 | H26: =H$5*(1+A_pore*H$6*($A26/100))/(1-H$6*(1+((1-phimax_pore)/phimax_pore^2)*($A26/100))*($A26/100)) -> 2.6248906 | I26: =I$5*(1+A_pore*I$6*($A26/100))/(1-I$6*(1+((1-phimax_pore)/phimax_pore^2)*($A26/100))*($A26/100)) -> 2.6371118 | ... AK26: =AK$5*(1+A_pore*AK$6*($A26/100))/(1-AK$6*(1+((1-phimax_pore)/phimax_pore^2)*($A26/100))*($A26/100)) -> 3.1339377
A27: 18 | B27: =B$5*(1+A_pore*B$6*($A27/100))/(1-B$6*(1+((1-phimax_pore)/phimax_pore^2)*($A27/100))*($A27/100)) -> 2.5155613 | C27: =C$5*(1+A_pore*C$6*($A27/100))/(1-C$6*(1+((1-phimax_pore)/phimax_pore^2)*($A27/100))*($A27/100)) -> 2.5259542 | D27: =D$5*(1+A_pore*D$6*($A27/100))/(1-D$6*(1+((1-phimax_pore)/phimax_pore^2)*($A27/100))*($A27/100)) -> 2.536556 | E27: =E$5*(1+A_pore*E$6*($A27/100))/(1-E$6*(1+((1-phimax_pore)/phimax_pore^2)*($A27/100))*($A27/100)) -> 2.5473733 | F27: =F$5*(1+A_pore*F$6*($A27/100))/(1-F$6*(1+((1-phimax_pore)/phimax_pore^2)*($A27/100))*($A27/100)) -> 2.558413 | G27: =G$5*(1+A_pore*G$6*($A27/100))/(1-G$6*(1+((1-phimax_pore)/phimax_pore^2)*($A27/100))*($A27/100)) -> 2.5696821 | H27: =H$5*(1+A_pore*H$6*($A27/100))/(1-H$6*(1+((1-phimax_pore)/phimax_pore^2)*($A27/100))*($A27/100)) -> 2.5811882 | I27: =I$5*(1+A_pore*I$6*($A27/100))/(1-I$6*(1+((1-phimax_pore)/phimax_pore^2)*($A27/100))*($A27/100)) -> 2.592939 | ... AK27: =AK$5*(1+A_pore*AK$6*($A27/100))/(1-AK$6*(1+((1-phimax_pore)/phimax_pore^2)*($A27/100))*($A27/100)) -> 3.0694863
A28: 19 | B28: =B$5*(1+A_pore*B$6*($A28/100))/(1-B$6*(1+((1-phimax_pore)/phimax_pore^2)*($A28/100))*($A28/100)) -> 2.4756242 | C28: =C$5*(1+A_pore*C$6*($A28/100))/(1-C$6*(1+((1-phimax_pore)/phimax_pore^2)*($A28/100))*($A28/100)) -> 2.4856271 | D28: =D$5*(1+A_pore*D$6*($A28/100))/(1-D$6*(1+((1-phimax_pore)/phimax_pore^2)*($A28/100))*($A28/100)) -> 2.4958298 | E28: =E$5*(1+A_pore*E$6*($A28/100))/(1-E$6*(1+((1-phimax_pore)/phimax_pore^2)*($A28/100))*($A28/100)) -> 2.5062388 | F28: =F$5*(1+A_pore*F$6*($A28/100))/(1-F$6*(1+((1-phimax_pore)/phimax_pore^2)*($A28/100))*($A28/100)) -> 2.5168604 | G28: =G$5*(1+A_pore*G$6*($A28/100))/(1-G$6*(1+((1-phimax_pore)/phimax_pore^2)*($A28/100))*($A28/100)) -> 2.5277015 | H28: =H$5*(1+A_pore*H$6*($A28/100))/(1-H$6*(1+((1-phimax_pore)/phimax_pore^2)*($A28/100))*($A28/100)) -> 2.5387692 | I28: =I$5*(1+A_pore*I$6*($A28/100))/(1-I$6*(1+((1-phimax_pore)/phimax_pore^2)*($A28/100))*($A28/100)) -> 2.5500709 | ... AK28: =AK$5*(1+A_pore*AK$6*($A28/100))/(1-AK$6*(1+((1-phimax_pore)/phimax_pore^2)*($A28/100))*($A28/100)) -> 3.0073456
A29: 20 | B29: =B$5*(1+A_pore*B$6*($A29/100))/(1-B$6*(1+((1-phimax_pore)/phimax_pore^2)*($A29/100))*($A29/100)) -> 2.4368055 | C29: =C$5*(1+A_pore*C$6*($A29/100))/(1-C$6*(1+((1-phimax_pore)/phimax_pore^2)*($A29/100))*($A29/100)) -> 2.4464353 | D29: =D$5*(1+A_pore*D$6*($A29/100))/(1-D$6*(1+((1-phimax_pore)/phimax_pore^2)*($A29/100))*($A29/100)) -> 2.4562565 | E29: =E$5*(1+A_pore*E$6*($A29/100))/(1-E$6*(1+((1-phimax_pore)/phimax_pore^2)*($A29/100))*($A29/100)) -> 2.466275 | F29: =F$5*(1+A_pore*F$6*($A29/100))/(1-F$6*(1+((1-phimax_pore)/phimax_pore^2)*($A29/100))*($A29/100)) -> 2.476497 | G29: =G$5*(1+A_pore*G$6*($A29/100))/(1-G$6*(1+((1-phimax_pore)/phimax_pore^2)*($A29/100))*($A29/100)) -> 2.4869291 | H29: =H$5*(1+A_pore*H$6*($A29/100))/(1-H$6*(1+((1-phimax_pore)/phimax_pore^2)*($A29/100))*($A29/100)) -> 2.4975779 | I29: =I$5*(1+A_pore*I$6*($A29/100))/(1-I$6*(1+((1-phimax_pore)/phimax_pore^2)*($A29/100))*($A29/100)) -> 2.5084505 | ... AK29: =AK$5*(1+A_pore*AK$6*($A29/100))/(1-AK$6*(1+((1-phimax_pore)/phimax_pore^2)*($A29/100))*($A29/100)) -> 2.9473937
... A104: 95 | B104: =B$5*(1+A_pore*B$6*($A104/100))/(1-B$6*(1+((1-phimax_pore)/phimax_pore^2)*($A104/100))*($A104/100)) -> 1.0372427 | C104: =C$5*(1+A_pore*C$6*($A104/100))/(1-C$6*(1+((1-phimax_pore)/phimax_pore^2)*($A104/100))*($A104/100)) -> 1.0373983 | D104: =D$5*(1+A_pore*D$6*($A104/100))/(1-D$6*(1+((1-phimax_pore)/phimax_pore^2)*($A104/100))*($A104/100)) -> 1.0375567 | E104: =E$5*(1+A_pore*E$6*($A104/100))/(1-E$6*(1+((1-phimax_pore)/phimax_pore^2)*($A104/100))*($A104/100)) -> 1.0377179 | F104: =F$5*(1+A_pore*F$6*($A104/100))/(1-F$6*(1+((1-phimax_pore)/phimax_pore^2)*($A104/100))*($A104/100)) -> 1.0378819 | G104: =G$5*(1+A_pore*G$6*($A104/100))/(1-G$6*(1+((1-phimax_pore)/phimax_pore^2)*($A104/100))*($A104/100)) -> 1.038049 | H104: =H$5*(1+A_pore*H$6*($A104/100))/(1-H$6*(1+((1-phimax_pore)/phimax_pore^2)*($A104/100))*($A104/100)) -> 1.0382191 | I104: =I$5*(1+A_pore*I$6*($A104/100))/(1-I$6*(1+((1-phimax_pore)/phimax_pore^2)*($A104/100))*($A104/100)) -> 1.0383923 | ... AK104: =AK$5*(1+A_pore*AK$6*($A104/100))/(1-AK$6*(1+((1-phimax_pore)/phimax_pore^2)*($A104/100))*($A104/100)) -> 1.0451384

Sheet Fig4b_LamMap
A1: Figure 4b: lambda design map, W m-1 K-1 (three-phase LN model)
A2: helper rows: 3 = h-BN wt%, 4 = phi_BN, 5 = dense-composite property, 6 = B_pore. Grid from row 8: rows = porosity (%), columns = wt%.
A3: wt% -> | B3: 0 | C3: 2 | D3: 4 | E3: 6 | F3: 8 | G3: 10 | H3: 12 | I3: 14 | J3: 16 | K3: 18 | L3: 20 | M3: 22 | N3: 24 | O3: 26 | P3: 28 | Q3: 30 | R3: 32 | S3: 34 | T3: 36 | U3: 38 | V3: 40 | W3: 42 | X3: 44 | Y3: 46 | Z3: 48 | AA3: 50 | AB3: 52 | AC3: 54 | AD3: 56 | AE3: 58 | AF3: 60 | AG3: 62 | AH3: 64 | AI3: 66 | AJ3: 68 | AK3: 70
A4: phi_BN | B4: =IF(B$3=0,0,(B$3/100/rho_BN)/((B$3/100/rho_BN)+((1-B$3/100)/rho_PI))) -> 0 | C4: =IF(C$3=0,0,(C$3/100/rho_BN)/((C$3/100/rho_BN)+((1-C$3/100)/rho_PI))) -> 0.0124967 | D4: =IF(D$3=0,0,(D$3/100/rho_BN)/((D$3/100/rho_BN)+((1-D$3/100)/rho_PI))) -> 0.025186236 | E4: =IF(E$3=0,0,(E$3/100/rho_BN)/((E$3/100/rho_BN)+((1-E$3/100)/rho_PI))) -> 0.038073108 | F4: =IF(F$3=0,0,(F$3/100/rho_BN)/((F$3/100/rho_BN)+((1-F$3/100)/rho_PI))) -> 0.051161953 | G4: =IF(G$3=0,0,(G$3/100/rho_BN)/((G$3/100/rho_BN)+((1-G$3/100)/rho_PI))) -> 0.064457558 | H4: =IF(H$3=0,0,(H$3/100/rho_BN)/((H$3/100/rho_BN)+((1-H$3/100)/rho_PI))) -> 0.077964861 | I4: =IF(I$3=0,0,(I$3/100/rho_BN)/((I$3/100/rho_BN)+((1-I$3/100)/rho_PI))) -> 0.091688959 | ... AK4: =IF(AK$3=0,0,(AK$3/100/rho_BN)/((AK$3/100/rho_BN)+((1-AK$3/100)/rho_PI))) -> 0.59131469
A5: dense property | B5: =lam_PI*(1+A_BN_lam*((lam_BN_eff/lam_PI-1)/(lam_BN_eff/lam_PI+A_BN_lam))*B$4)/(1-((lam_BN_eff/lam_PI-1)/(lam_BN_eff/lam_PI+A_BN_lam))*(1+((1-phimax_BN_lam)/phimax_BN_lam^2)*B$4)*B$4) -> 0.12 | C5: =lam_PI*(1+A_BN_lam*((lam_BN_eff/lam_PI-1)/(lam_BN_eff/lam_PI+A_BN_lam))*C$4)/(1-((lam_BN_eff/lam_PI-1)/(lam_BN_eff/lam_PI+A_BN_lam))*(1+((1-phimax_BN_lam)/phimax_BN_lam^2)*C$4)*C$4) -> 0.12884868 | D5: =lam_PI*(1+A_BN_lam*((lam_BN_eff/lam_PI-1)/(lam_BN_eff/lam_PI+A_BN_lam))*D$4)/(1-((lam_BN_eff/lam_PI-1)/(lam_BN_eff/lam_PI+A_BN_lam))*(1+((1-phimax_BN_lam)/phimax_BN_lam^2)*D$4)*D$4) -> 0.13808914 | E5: =lam_PI*(1+A_BN_lam*((lam_BN_eff/lam_PI-1)/(lam_BN_eff/lam_PI+A_BN_lam))*E$4)/(1-((lam_BN_eff/lam_PI-1)/(lam_BN_eff/lam_PI+A_BN_lam))*(1+((1-phimax_BN_lam)/phimax_BN_lam^2)*E$4)*E$4) -> 0.14775566 | F5: =lam_PI*(1+A_BN_lam*((lam_BN_eff/lam_PI-1)/(lam_BN_eff/lam_PI+A_BN_lam))*F$4)/(1-((lam_BN_eff/lam_PI-1)/(lam_BN_eff/lam_PI+A_BN_lam))*(1+((1-phimax_BN_lam)/phimax_BN_lam^2)*F$4)*F$4) -> 0.1578866 | G5: =lam_PI*(1+A_BN_lam*((lam_BN_eff/lam_PI-1)/(lam_BN_eff/lam_PI+A_BN_lam))*G$4)/(1-((lam_BN_eff/lam_PI-1)/(lam_BN_eff/lam_PI+A_BN_lam))*(1+((1-phimax_BN_lam)/phimax_BN_lam^2)*G$4)*G$4) -> 0.16852505 | H5: =lam_PI*(1+A_BN_lam*((lam_BN_eff/lam_PI-1)/(lam_BN_eff/lam_PI+A_BN_lam))*H$4)/(1-((lam_BN_eff/lam_PI-1)/(lam_BN_eff/lam_PI+A_BN_lam))*(1+((1-phimax_BN_lam)/phimax_BN_lam^2)*H$4)*H$4) -> 0.17971961 | I5: =lam_PI*(1+A_BN_lam*((lam_BN_eff/lam_PI-1)/(lam_BN_eff/lam_PI+A_BN_lam))*I$4)/(1-((lam_BN_eff/lam_PI-1)/(lam_BN_eff/lam_PI+A_BN_lam))*(1+((1-phimax_BN_lam)/phimax_BN_lam^2)*I$4)*I$4) -> 0.19152523 | ... AK5: =lam_PI*(1+A_BN_lam*((lam_BN_eff/lam_PI-1)/(lam_BN_eff/lam_PI+A_BN_lam))*AK$4)/(1-((lam_BN_eff/lam_PI-1)/(lam_BN_eff/lam_PI+A_BN_lam))*(1+((1-phimax_BN_lam)/phimax_BN_lam^2)*AK$4)*AK$4) -> 3.833034
A6: B_pore | B6: =(lam_air/B$5-1)/(lam_air/B$5+A_pore) -> -2.6404494 | C6: =(lam_air/C$5-1)/(lam_air/C$5+A_pore) -> -2.8326809 | D6: =(lam_air/D$5-1)/(lam_air/D$5+A_pore) -> -3.0255822 | E6: =(lam_air/E$5-1)/(lam_air/E$5+A_pore) -> -3.2193073 | F6: =(lam_air/F$5-1)/(lam_air/F$5+A_pore) -> -3.4140158 | G6: =(lam_air/G$5-1)/(lam_air/G$5+A_pore) -> -3.6098738 | H6: =(lam_air/H$5-1)/(lam_air/H$5+A_pore) -> -3.8070546 | I6: =(lam_air/I$5-1)/(lam_air/I$5+A_pore) -> -4.0057392 | ... AK6: =(lam_air/AK$5-1)/(lam_air/AK$5+A_pore) -> -11.444814
A8: porosity (%) \ wt% | B8: =B$3 -> 0 | C8: =C$3 -> 2 | D8: =D$3 -> 4 | E8: =E$3 -> 6 | F8: =F$3 -> 8 | G8: =G$3 -> 10 | H8: =H$3 -> 12 | I8: =I$3 -> 14 | ... AK8: =AK$3 -> 70 | AN8: Measured overlay (for symbols and NP->HP arrows)
A9: 0 | B9: =B$5*(1+A_pore*B$6*($A9/100))/(1-B$6*(1+((1-phimax_pore)/phimax_pore^2)*($A9/100))*($A9/100)) -> 0.12 | C9: =C$5*(1+A_pore*C$6*($A9/100))/(1-C$6*(1+((1-phimax_pore)/phimax_pore^2)*($A9/100))*($A9/100)) -> 0.12884868 | D9: =D$5*(1+A_pore*D$6*($A9/100))/(1-D$6*(1+((1-phimax_pore)/phimax_pore^2)*($A9/100))*($A9/100)) -> 0.13808914 | E9: =E$5*(1+A_pore*E$6*($A9/100))/(1-E$6*(1+((1-phimax_pore)/phimax_pore^2)*($A9/100))*($A9/100)) -> 0.14775566 | F9: =F$5*(1+A_pore*F$6*($A9/100))/(1-F$6*(1+((1-phimax_pore)/phimax_pore^2)*($A9/100))*($A9/100)) -> 0.1578866 | G9: =G$5*(1+A_pore*G$6*($A9/100))/(1-G$6*(1+((1-phimax_pore)/phimax_pore^2)*($A9/100))*($A9/100)) -> 0.16852505 | H9: =H$5*(1+A_pore*H$6*($A9/100))/(1-H$6*(1+((1-phimax_pore)/phimax_pore^2)*($A9/100))*($A9/100)) -> 0.17971961 | I9: =I$5*(1+A_pore*I$6*($A9/100))/(1-I$6*(1+((1-phimax_pore)/phimax_pore^2)*($A9/100))*($A9/100)) -> 0.19152523 | ... AK9: =AK$5*(1+A_pore*AK$6*($A9/100))/(1-AK$6*(1+((1-phimax_pore)/phimax_pore^2)*($A9/100))*($A9/100)) -> 3.833034 | AN9: h-BN (wt%) | AO9: phi_open NP (%) | AP9: phi_open HP (%) | AQ9: arrow dx | AR9: arrow dy
A10: 1 | B10: =B$5*(1+A_pore*B$6*($A10/100))/(1-B$6*(1+((1-phimax_pore)/phimax_pore^2)*($A10/100))*($A10/100)) -> 0.1166657 | C10: =C$5*(1+A_pore*C$6*($A10/100))/(1-C$6*(1+((1-phimax_pore)/phimax_pore^2)*($A10/100))*($A10/100)) -> 0.12501505 | D10: =D$5*(1+A_pore*D$6*($A10/100))/(1-D$6*(1+((1-phimax_pore)/phimax_pore^2)*($A10/100))*($A10/100)) -> 0.13370901 | E10: =E$5*(1+A_pore*E$6*($A10/100))/(1-E$6*(1+((1-phimax_pore)/phimax_pore^2)*($A10/100))*($A10/100)) -> 0.14277819 | F10: =F$5*(1+A_pore*F$6*($A10/100))/(1-F$6*(1+((1-phimax_pore)/phimax_pore^2)*($A10/100))*($A10/100)) -> 0.15225678 | G10: =G$5*(1+A_pore*G$6*($A10/100))/(1-G$6*(1+((1-phimax_pore)/phimax_pore^2)*($A10/100))*($A10/100)) -> 0.16218317 | H10: =H$5*(1+A_pore*H$6*($A10/100))/(1-H$6*(1+((1-phimax_pore)/phimax_pore^2)*($A10/100))*($A10/100)) -> 0.17260058 | I10: =I$5*(1+A_pore*I$6*($A10/100))/(1-I$6*(1+((1-phimax_pore)/phimax_pore^2)*($A10/100))*($A10/100)) -> 0.18355787 | ... AK10: =AK$5*(1+A_pore*AK$6*($A10/100))/(1-AK$6*(1+((1-phimax_pore)/phimax_pore^2)*($A10/100))*($A10/100)) -> 3.4078746 | AN10: 0 | AO10: =Samples!C4 -> 75.4 | AP10: =Samples!C9 -> 43.4 | AQ10: 0 | AR10: =AP10-AO10 -> -32
A11: 2 | B11: =B$5*(1+A_pore*B$6*($A11/100))/(1-B$6*(1+((1-phimax_pore)/phimax_pore^2)*($A11/100))*($A11/100)) -> 0.11349809 | C11: =C$5*(1+A_pore*C$6*($A11/100))/(1-C$6*(1+((1-phimax_pore)/phimax_pore^2)*($A11/100))*($A11/100)) -> 0.12138632 | D11: =D$5*(1+A_pore*D$6*($A11/100))/(1-D$6*(1+((1-phimax_pore)/phimax_pore^2)*($A11/100))*($A11/100)) -> 0.12957808 | E11: =E$5*(1+A_pore*E$6*($A11/100))/(1-E$6*(1+((1-phimax_pore)/phimax_pore^2)*($A11/100))*($A11/100)) -> 0.13810098 | F11: =F$5*(1+A_pore*F$6*($A11/100))/(1-F$6*(1+((1-phimax_pore)/phimax_pore^2)*($A11/100))*($A11/100)) -> 0.14698587 | G11: =G$5*(1+A_pore*G$6*($A11/100))/(1-G$6*(1+((1-phimax_pore)/phimax_pore^2)*($A11/100))*($A11/100)) -> 0.15626728 | H11: =H$5*(1+A_pore*H$6*($A11/100))/(1-H$6*(1+((1-phimax_pore)/phimax_pore^2)*($A11/100))*($A11/100)) -> 0.1659841 | I11: =I$5*(1+A_pore*I$6*($A11/100))/(1-I$6*(1+((1-phimax_pore)/phimax_pore^2)*($A11/100))*($A11/100)) -> 0.17618019 | ... AK11: =AK$5*(1+A_pore*AK$6*($A11/100))/(1-AK$6*(1+((1-phimax_pore)/phimax_pore^2)*($A11/100))*($A11/100)) -> 3.0618545 | AN11: 10 | AO11: =Samples!C5 -> 91.4 | AP11: =Samples!C10 -> 29.8 | AQ11: 0 | AR11: =AP11-AO11 -> -61.6
A12: 3 | B12: =B$5*(1+A_pore*B$6*($A12/100))/(1-B$6*(1+((1-phimax_pore)/phimax_pore^2)*($A12/100))*($A12/100)) -> 0.11048497 | C12: =C$5*(1+A_pore*C$6*($A12/100))/(1-C$6*(1+((1-phimax_pore)/phimax_pore^2)*($A12/100))*($A12/100)) -> 0.1179465 | D12: =D$5*(1+A_pore*D$6*($A12/100))/(1-D$6*(1+((1-phimax_pore)/phimax_pore^2)*($A12/100))*($A12/100)) -> 0.12567567 | E12: =E$5*(1+A_pore*E$6*($A12/100))/(1-E$6*(1+((1-phimax_pore)/phimax_pore^2)*($A12/100))*($A12/100)) -> 0.13369768 | F12: =F$5*(1+A_pore*F$6*($A12/100))/(1-F$6*(1+((1-phimax_pore)/phimax_pore^2)*($A12/100))*($A12/100)) -> 0.14204061 | G12: =G$5*(1+A_pore*G$6*($A12/100))/(1-G$6*(1+((1-phimax_pore)/phimax_pore^2)*($A12/100))*($A12/100)) -> 0.15073588 | H12: =H$5*(1+A_pore*H$6*($A12/100))/(1-H$6*(1+((1-phimax_pore)/phimax_pore^2)*($A12/100))*($A12/100)) -> 0.15981877 | I12: =I$5*(1+A_pore*I$6*($A12/100))/(1-I$6*(1+((1-phimax_pore)/phimax_pore^2)*($A12/100))*($A12/100)) -> 0.16932907 | ... AK12: =AK$5*(1+A_pore*AK$6*($A12/100))/(1-AK$6*(1+((1-phimax_pore)/phimax_pore^2)*($A12/100))*($A12/100)) -> 2.77476 | AN12: 30 | AO12: =Samples!C6 -> 48.8 | AP12: =Samples!C11 -> 67.2 | AQ12: 0 | AR12: =AP12-AO12 -> 18.4
A13: 4 | B13: =B$5*(1+A_pore*B$6*($A13/100))/(1-B$6*(1+((1-phimax_pore)/phimax_pore^2)*($A13/100))*($A13/100)) -> 0.10761532 | C13: =C$5*(1+A_pore*C$6*($A13/100))/(1-C$6*(1+((1-phimax_pore)/phimax_pore^2)*($A13/100))*($A13/100)) -> 0.11468121 | D13: =D$5*(1+A_pore*D$6*($A13/100))/(1-D$6*(1+((1-phimax_pore)/phimax_pore^2)*($A13/100))*($A13/100)) -> 0.12198333 | E13: =E$5*(1+A_pore*E$6*($A13/100))/(1-E$6*(1+((1-phimax_pore)/phimax_pore^2)*($A13/100))*($A13/100)) -> 0.12954491 | F13: =F$5*(1+A_pore*F$6*($A13/100))/(1-F$6*(1+((1-phimax_pore)/phimax_pore^2)*($A13/100))*($A13/100)) -> 0.13739175 | G13: =G$5*(1+A_pore*G$6*($A13/100))/(1-G$6*(1+((1-phimax_pore)/phimax_pore^2)*($A13/100))*($A13/100)) -> 0.14555267 | H13: =H$5*(1+A_pore*H$6*($A13/100))/(1-H$6*(1+((1-phimax_pore)/phimax_pore^2)*($A13/100))*($A13/100)) -> 0.15405999 | I13: =I$5*(1+A_pore*I$6*($A13/100))/(1-I$6*(1+((1-phimax_pore)/phimax_pore^2)*($A13/100))*($A13/100)) -> 0.16295011 | ... AK13: =AK$5*(1+A_pore*AK$6*($A13/100))/(1-AK$6*(1+((1-phimax_pore)/phimax_pore^2)*($A13/100))*($A13/100)) -> 2.5327212 | AN13: 50 | AO13: =Samples!C7 -> 58.1 | AP13: =Samples!C12 -> 64.6 | AQ13: 0 | AR13: =AP13-AO13 -> 6.5
